Workbook

Sheet RESUMEN
C1: c30 | E1: b31
C2: dolares | D2: colones | E2: dolares | F2: colones
B3: 2024 | C3: =+'2024 c30'!Q2992 -> 0 | D3: =+'2024 c30'!P2992 -> 702.68 | E3: =+'2024 b31'!Q2987 -> 32951 | F3: =+'2024 b31'!P2987 -> 99121382
B4: 2025 | E4: =+Table13[[#Totals],[Dolares]] -> 361.2 | F4: =+Table13[[#Totals],[Colones]] -> 74705744
C5: =SUM(C3:C4) -> 0 | D5: =SUM(D3:D4) -> 702.68 | E5: =SUM(E3:E4) -> 33312.2 | F5: =SUM(F3:F4) -> 1.7382713e+08
D8: =+C5+D5/500 -> 1.40536 | F8: =+E5+F5/500 -> 380966.45 | G8: gastos al 6 de junio
G9: gastos de los ultimos 2 meses por actualizar de contabilidad
F10: =+'CIERRE de b31'!C27 -> 333673.35 | G10: proyeccion de cierre
F12: =SUM(F8:F10) -> 714639.8
F14: 35638.26 | G14: en cuentas al 18 de agosto

Sheet CIERRE de b31
B1: ITEM | C1: COSTO | D1: CONTRATISTA | E1: COTIZACIONES
B2: VENTANAS | C2: =30146500/500 -> 60293 | E2: vidrios brenes Europa, Bellavida Eurovista esperando
B3: MANO DE OBRA, con liquidaciones | C3: =10*4200*1.37 -> 57540
B4: CIELOS DE MADERA | C4: =348*110*1.13 -> 43256.4 | E4: Vidal Teca wash wash $110/m2
B5: MUEBLES FIJOS | C5: 42000 | E5: Atos, Vidal, The kitchen
B6: PISOS | C6: =479*(40+15+6) -> 29219 | E6: porcelanato y coralina
B7: JARDINERIA | C7: 15000 | E7: Isaac
B8: LUMINARIAS | C8: =+(1715846+458292)/502 -> 4330.9522 | E8: Ledinside
B9: ACABADOS PINTURA, CIELOS GYPSUM, EMPASTES | C9: =619*15 -> 9285
B10: LOZA SANITARIA Y GRIFERIA | C10: 8960 | E10: Helvex
B11: ELECTRODOMESTICOS | C11: 8000
B12: PISCINA EQUIPOS | C12: 7800 | E12: Smartengineering
B13: AIRES ACONDICIONADOS | C13: =1850*4 -> 7400 | D13: Josue
B14: CERRAMIENTOS | C14: 6350
B15: PUERTAS | C15: =40%*13150 -> 5260 | D15: Vidal
B16: TANQUE DE AGUA Y SISTEMA DE PRESION, mas excavacion | C16: =4200+850 -> 5050 | E16: Smartengineering
B17: ENCHAPES baños | C17: =101*(20+24+5) -> 4949 | E17: porcelanato de 7.5x30cm
B18: PISCINA ENCHAPES | C18: =62*(30+20+6) -> 3472 | E18: porcelanato
B19: PINTURA DE CUBIERTA | C19: 2800
B20: MAMPARAS DE VIDRIO EN BAÑOS | C20: 2500 | D20: Vidrios quiros
B21: HOJALATERIA | C21: =1100000/500 -> 2200 | D21: hector carmona
B22: PLAQUERIA GENERAL | C22: 2152
B23: CERRAJERIA | C23: =14*145 -> 2030
B24: PRECINTAS | C24: 2026
B25: PORTON FRONTAL | C25: 1800
C27: =SUM(C2:C25) -> 333673.35
B29: No hay cochera
B32: =TODAY() -> 45954
B33: =18*7 -> 126
A34: 45781 | B34: =+B32+B33 -> 46080

Sheet 2024 c30
G1: id iguales? | H1: =SUM(B:B) -> 0
G2: id consecutivos? | H2: =SUM(C:C) -> 515
G3: sin precio | H3: =SUM(D:D) -> 2
G4: sin formade pago | H4: =SUM(E:E) -> 76
G5: sin centro de costo | H5: =SUM(F:F) -> 0
B7: id iguales? | C7: id consecutivos? | D7: sin precio | E7: sin formade pago | F7: sin centro de costo | G7: identificador | H7: Fecha | I7: diario | P7: colones | Q7: dolares | R7: Tipo Cambio | S7: Precio en $ | T7: Descripcion | U7: forma de pago | W7: Observaciones
J8: =+IF(I8<10,_xlfn.CONCAT("0",I8),I8) -> 0 | K8: =+YEAR(H8)-2000 -> -100 | L8: =+MONTH(H8) -> 1 | M8: =+DAY(H8) -> 0 | N8: =+IF(L8<10,_xlfn.CONCAT("0",L8),L8) -> 01 | O8: =+IF(M8<10,_xlfn.CONCAT("0",M8),M8) -> 00
J9: =+IF(I9<10,_xlfn.CONCAT("0",I9),I9) -> 0 | K9: =+YEAR(H9)-2000 -> -100 | L9: =+MONTH(H9) -> 1 | M9: =+DAY(H9) -> 0 | N9: =+IF(L9<10,_xlfn.CONCAT("0",L9),L9) -> 01 | O9: =+IF(M9<10,_xlfn.CONCAT("0",M9),M9) -> 00
P10: =SUM(P1:P9) -> 0 | Q10: =SUM(Q1:Q9) -> 0 | R10: =SUM(R1:R9) -> 0 | S10: =SUM(S1:S9) -> 0 | V10: PGE C30
A11: 519 | B11: =IF(G11="-",0,IF(G10=G11,1,0)) -> 0 | C11: =+IF(G11="-",0,IF(I11=I10+1,0,(IF(I11=1,0,1)))) -> 1 | D11: =+IF(AND(P11="",Q11=""),1,0) -> 0 | E11: =IF(U11="",1,0) -> 0 | F11: =IF(V11="",1,0) -> 0 | G11: =IF(H11=0,"-",_xlfn.CONCAT(K11,N11,O11,J11)) -> 24051414 | H11: 45426 | I11: 14 | J11: =+IF(I11<10,_xlfn.CONCAT("0",I11),I11) -> 14 | K11: =+YEAR(H11)-2000 -> 24 | L11: =+MONTH(H11) -> 5 | M11: =+DAY(H11) -> 14 | N11: =+IF(L11<10,_xlfn.CONCAT("0",L11),L11) -> 05 | O11: =+IF(M11<10,_xlfn.CONCAT("0",M11),M11) -> 14 | Q11: 131436 | T11: Helvex - PG-1740 | U11: BacD | V11: PGE C30
J14: =+IF(I14<10,_xlfn.CONCAT("0",I14),I14) -> 0 | K14: =+YEAR(H14)-2000 -> -100 | L14: =+MONTH(H14) -> 1 | M14: =+DAY(H14) -> 0 | N14: =+IF(L14<10,_xlfn.CONCAT("0",L14),L14) -> 01 | O14: =+IF(M14<10,_xlfn.CONCAT("0",M14),M14) -> 00
J15: =+IF(I15<10,_xlfn.CONCAT("0",I15),I15) -> 0 | K15: =+YEAR(H15)-2000 -> -100 | L15: =+MONTH(H15) -> 1 | M15: =+DAY(H15) -> 0 | N15: =+IF(L15<10,_xlfn.CONCAT("0",L15),L15) -> 01 | O15: =+IF(M15<10,_xlfn.CONCAT("0",M15),M15) -> 00
J16: =+IF(I16<10,_xlfn.CONCAT("0",I16),I16) -> 0 | K16: =+YEAR(H16)-2000 -> -100 | L16: =+MONTH(H16) -> 1 | M16: =+DAY(H16) -> 0 | N16: =+IF(L16<10,_xlfn.CONCAT("0",L16),L16) -> 01 | O16: =+IF(M16<10,_xlfn.CONCAT("0",M16),M16) -> 00
J17: =+IF(I17<10,_xlfn.CONCAT("0",I17),I17) -> 0 | K17: =+YEAR(H17)-2000 -> -100 | L17: =+MONTH(H17) -> 1 | M17: =+DAY(H17) -> 0 | N17: =+IF(L17<10,_xlfn.CONCAT("0",L17),L17) -> 01 | O17: =+IF(M17<10,_xlfn.CONCAT("0",M17),M17) -> 00
A18: 295 | B18: =IF(G18="-",0,IF(G17=G18,1,0)) -> 0 | C18: =+IF(G18="-",0,IF(I18=I17+1,0,(IF(I18=1,0,1)))) -> 1 | D18: =+IF(AND(P18="",Q18=""),1,0) -> 0 | E18: =IF(U18="",1,0) -> 0 | F18: =IF(V18="",1,0) -> 0 | G18: =IF(H18=0,"-",_xlfn.CONCAT(K18,N18,O18,J18)) -> 24042602 | H18: 45408 | I18: 2 | J18: =+IF(I18<10,_xlfn.CONCAT("0",I18),I18) -> 02 | K18: =+YEAR(H18)-2000 -> 24 | L18: =+MONTH(H18) -> 4 | M18: =+DAY(H18) -> 26 | N18: =+IF(L18<10,_xlfn.CONCAT("0",L18),L18) -> 04 | O18: =+IF(M18<10,_xlfn.CONCAT("0",M18),M18) -> 26 | Q18: 16588.75 | T18: ATOS Muebles Fijos | U18: BacC | V18: PGE C30
J19: =+IF(I19<10,_xlfn.CONCAT("0",I19),I19) -> 0 | K19: =+YEAR(H19)-2000 -> -100 | L19: =+MONTH(H19) -> 1 | M19: =+DAY(H19) -> 0 | N19: =+IF(L19<10,_xlfn.CONCAT("0",L19),L19) -> 01 | O19: =+IF(M19<10,_xlfn.CONCAT("0",M19),M19) -> 00
J20: =+IF(I20<10,_xlfn.CONCAT("0",I20),I20) -> 0 | K20: =+YEAR(H20)-2000 -> -100 | L20: =+MONTH(H20) -> 1 | M20: =+DAY(H20) -> 0 | N20: =+IF(L20<10,_xlfn.CONCAT("0",L20),L20) -> 01 | O20: =+IF(M20<10,_xlfn.CONCAT("0",M20),M20) -> 00
J21: =+IF(I21<10,_xlfn.CONCAT("0",I21),I21) -> 0 | K21: =+YEAR(H21)-2000 -> -100 | L21: =+MONTH(H21) -> 1 | M21: =+DAY(H21) -> 0 | N21: =+IF(L21<10,_xlfn.CONCAT("0",L21),L21) -> 01 | O21: =+IF(M21<10,_xlfn.CONCAT("0",M21),M21) -> 00
J22: =+IF(I22<10,_xlfn.CONCAT("0",I22),I22) -> 0 | K22: =+YEAR(H22)-2000 -> -100 | L22: =+MONTH(H22) -> 1 | M22: =+DAY(H22) -> 0 | N22: =+IF(L22<10,_xlfn.CONCAT("0",L22),L22) -> 01 | O22: =+IF(M22<10,_xlfn.CONCAT("0",M22),M22) -> 00
J23: =+IF(I23<10,_xlfn.CONCAT("0",I23),I23) -> 0 | K23: =+YEAR(H23)-2000 -> -100 | L23: =+MONTH(H23) -> 1 | M23: =+DAY(H23) -> 0 | N23: =+IF(L23<10,_xlfn.CONCAT("0",L23),L23) -> 01 | O23: =+IF(M23<10,_xlfn.CONCAT("0",M23),M23) -> 00
J24: =+IF(I24<10,_xlfn.CONCAT("0",I24),I24) -> 0 | K24: =+YEAR(H24)-2000 -> -100 | L24: =+MONTH(H24) -> 1 | M24: =+DAY(H24) -> 0 | N24: =+IF(L24<10,_xlfn.CONCAT("0",L24),L24) -> 01 | O24: =+IF(M24<10,_xlfn.CONCAT("0",M24),M24) -> 00
J25: =+IF(I25<10,_xlfn.CONCAT("0",I25),I25) -> 0 | K25: =+YEAR(H25)-2000 -> -100 | L25: =+MONTH(H25) -> 1 | M25: =+DAY(H25) -> 0 | N25: =+IF(L25<10,_xlfn.CONCAT("0",L25),L25) -> 01 | O25: =+IF(M25<10,_xlfn.CONCAT("0",M25),M25) -> 00
A26: 437 | B26: =IF(G26="-",0,IF(G25=G26,1,0)) -> 0 | C26: =+IF(G26="-",0,IF(I26=I25+1,0,(IF(I26=1,0,1)))) -> 1 | D26: =+IF(AND(P26="",Q26=""),1,0) -> 0 | E26: =IF(U26="",1,0) -> 0 | F26: =IF(V26="",1,0) -> 0 | G26: =IF(H26=0,"-",_xlfn.CONCAT(K26,N26,O26,J26)) -> 24050904 | H26: 45421 | I26: 4 | J26: =+IF(I26<10,_xlfn.CONCAT("0",I26),I26) -> 04 | K26: =+YEAR(H26)-2000 -> 24 | L26: =+MONTH(H26) -> 5 | M26: =+DAY(H26) -> 9 | N26: =+IF(L26<10,_xlfn.CONCAT("0",L26),L26) -> 05 | O26: =+IF(M26<10,_xlfn.CONCAT("0",M26),M26) -> 09 | Q26: 10637.71 | T26: Poolmaxx Cancela Contrato de Piscina | U26: DavD | V26: PGE C30
J27: =+IF(I27<10,_xlfn.CONCAT("0",I27),I27) -> 0 | K27: =+YEAR(H27)-2000 -> -100 | L27: =+MONTH(H27) -> 1 | M27: =+DAY(H27) -> 0 | N27: =+IF(L27<10,_xlfn.CONCAT("0",L27),L27) -> 01 | O27: =+IF(M27<10,_xlfn.CONCAT("0",M27),M27) -> 00
J28: =+IF(I28<10,_xlfn.CONCAT("0",I28),I28) -> 0 | K28: =+YEAR(H28)-2000 -> -100 | L28: =+MONTH(H28) -> 1 | M28: =+DAY(H28) -> 0 | N28: =+IF(L28<10,_xlfn.CONCAT("0",L28),L28) -> 01 | O28: =+IF(M28<10,_xlfn.CONCAT("0",M28),M28) -> 00
J29: =+IF(I29<10,_xlfn.CONCAT("0",I29),I29) -> 0 | K29: =+YEAR(H29)-2000 -> -100 | L29: =+MONTH(H29) -> 1 | M29: =+DAY(H29) -> 0 | N29: =+IF(L29<10,_xlfn.CONCAT("0",L29),L29) -> 01 | O29: =+IF(M29<10,_xlfn.CONCAT("0",M29),M29) -> 00
J30: =+IF(I30<10,_xlfn.CONCAT("0",I30),I30) -> 0 | K30: =+YEAR(H30)-2000 -> -100 | L30: =+MONTH(H30) -> 1 | M30: =+DAY(H30) -> 0 | N30: =+IF(L30<10,_xlfn.CONCAT("0",L30),L30) -> 01 | O30: =+IF(M30<10,_xlfn.CONCAT("0",M30),M30) -> 00
J31: =+IF(I31<10,_xlfn.CONCAT("0",I31),I31) -> 0 | K31: =+YEAR(H31)-2000 -> -100 | L31: =+MONTH(H31) -> 1 | M31: =+DAY(H31) -> 0 | N31: =+IF(L31<10,_xlfn.CONCAT("0",L31),L31) -> 01 | O31: =+IF(M31<10,_xlfn.CONCAT("0",M31),M31) -> 00
J32: =+IF(I32<10,_xlfn.CONCAT("0",I32),I32) -> 0 | K32: =+YEAR(H32)-2000 -> -100 | L32: =+MONTH(H32) -> 1 | M32: =+DAY(H32) -> 0 | N32: =+IF(L32<10,_xlfn.CONCAT("0",L32),L32) -> 01 | O32: =+IF(M32<10,_xlfn.CONCAT("0",M32),M32) -> 00
J33: =+IF(I33<10,_xlfn.CONCAT("0",I33),I33) -> 0 | K33: =+YEAR(H33)-2000 -> -100 | L33: =+MONTH(H33) -> 1 | M33: =+DAY(H33) -> 0 | N33: =+IF(L33<10,_xlfn.CONCAT("0",L33),L33) -> 01 | O33: =+IF(M33<10,_xlfn.CONCAT("0",M33),M33) -> 00
J34: =+IF(I34<10,_xlfn.CONCAT("0",I34),I34) -> 0 | K34: =+YEAR(H34)-2000 -> -100 | L34: =+MONTH(H34) -> 1 | M34: =+DAY(H34) -> 0 | N34: =+IF(L34<10,_xlfn.CONCAT("0",L34),L34) -> 01 | O34: =+IF(M34<10,_xlfn.CONCAT("0",M34),M34) -> 00
J35: =+IF(I35<10,_xlfn.CONCAT("0",I35),I35) -> 0 | K35: =+YEAR(H35)-2000 -> -100 | L35: =+MONTH(H35) -> 1 | M35: =+DAY(H35) -> 0 | N35: =+IF(L35<10,_xlfn.CONCAT("0",L35),L35) -> 01 | O35: =+IF(M35<10,_xlfn.CONCAT("0",M35),M35) -> 00
J36: =+IF(I36<10,_xlfn.CONCAT("0",I36),I36) -> 0 | K36: =+YEAR(H36)-2000 -> -100 | L36: =+MONTH(H36) -> 1 | M36: =+DAY(H36) -> 0 | N36: =+IF(L36<10,_xlfn.CONCAT("0",L36),L36) -> 01 | O36: =+IF(M36<10,_xlfn.CONCAT("0",M36),M36) -> 00
J37: =+IF(I37<10,_xlfn.CONCAT("0",I37),I37) -> 0 | K37: =+YEAR(H37)-2000 -> -100 | L37: =+MONTH(H37) -> 1 | M37: =+DAY(H37) -> 0 | N37: =+IF(L37<10,_xlfn.CONCAT("0",L37),L37) -> 01 | O37: =+IF(M37<10,_xlfn.CONCAT("0",M37),M37) -> 00
J38: =+IF(I38<10,_xlfn.CONCAT("0",I38),I38) -> 0 | K38: =+YEAR(H38)-2000 -> -100 | L38: =+MONTH(H38) -> 1 | M38: =+DAY(H38) -> 0 | N38: =+IF(L38<10,_xlfn.CONCAT("0",L38),L38) -> 01 | O38: =+IF(M38<10,_xlfn.CONCAT("0",M38),M38) -> 00
... J40: =+IF(I40<10,_xlfn.CONCAT("0",I40),I40) -> 0 | K40: =+YEAR(H40)-2000 -> -100 | L40: =+MONTH(H40) -> 1 | M40: =+DAY(H40) -> 0 | N40: =+IF(L40<10,_xlfn.CONCAT("0",L40),L40) -> 01 | O40: =+IF(M40<10,_xlfn.CONCAT("0",M40),M40) -> 00
A41: 736 | B41: =IF(G41="-",0,IF(G39=G41,1,0)) -> 0 | C41: =+IF(G41="-",0,IF(I41=I39+1,0,(IF(I41=1,0,1)))) -> 1 | D41: =+IF(AND(P41="",Q41=""),1,0) -> 0 | E41: =IF(U41="",1,0) -> 0 | F41: =IF(V41="",1,0) -> 0 | G41: =IF(H41=0,"-",_xlfn.CONCAT(K41,N41,O41,J41)) -> 24060303 | H41: 45446 | I41: 3 | J41: =+IF(I41<10,_xlfn.CONCAT("0",I41),I41) -> 03 | K41: =+YEAR(H41)-2000 -> 24 | L41: =+MONTH(H41) -> 6 | M41: =+DAY(H41) -> 3 | N41: =+IF(L41<10,_xlfn.CONCAT("0",L41),L41) -> 06 | O41: =+IF(M41<10,_xlfn.CONCAT("0",M41),M41) -> 03 | Q41: 7327.5 | S41: =IFERROR(P41/R41,"") | T41: Atos DE OCCIDENTE SA - pago de muebles c30 | U41: DavD | V41: PGE C30
A42: 134 | B42: =IF(G42="-",0,IF(G41=G42,1,0)) -> 0 | C42: =+IF(G42="-",0,IF(I42=I41+1,0,(IF(I42=1,0,1)))) -> 0 | D42: =+IF(AND(P42="",Q42=""),1,0) -> 0 | E42: =IF(U42="",1,0) -> 0 | F42: =IF(V42="",1,0) -> 0 | G42: =IF(H42=0,"-",_xlfn.CONCAT(K42,N42,O42,J42)) -> 24041001 | H42: 45392 | I42: 1 | J42: =+IF(I42<10,_xlfn.CONCAT("0",I42),I42) -> 01 | K42: =+YEAR(H42)-2000 -> 24 | L42: =+MONTH(H42) -> 4 | M42: =+DAY(H42) -> 10 | N42: =+IF(L42<10,_xlfn.CONCAT("0",L42),L42) -> 04 | O42: =+IF(M42<10,_xlfn.CONCAT("0",M42),M42) -> 10 | Q42: =10109.83*0.7 -> 7076.881 | T42: Bella Vida CR - 70% adelanto ventanas 5ta habitacion | U42: BacD | V42: PGE C30
A43: 199 | B43: =IF(G43="-",0,IF(G42=G43,1,0)) -> 0 | C43: =+IF(G43="-",0,IF(I43=I42+1,0,(IF(I43=1,0,1)))) -> 1 | D43: =+IF(AND(P43="",Q43=""),1,0) -> 0 | E43: =IF(U43="",1,0) -> 0 | F43: =IF(V43="",1,0) -> 0 | G43: =IF(H43=0,"-",_xlfn.CONCAT(K43,N43,O43,J43)) -> 24041606 | H43: 45398 | I43: 6 | J43: =+IF(I43<10,_xlfn.CONCAT("0",I43),I43) -> 06 | K43: =+YEAR(H43)-2000 -> 24 | L43: =+MONTH(H43) -> 4 | M43: =+DAY(H43) -> 16 | N43: =+IF(L43<10,_xlfn.CONCAT("0",L43),L43) -> 04 | O43: =+IF(M43<10,_xlfn.CONCAT("0",M43),M43) -> 16 | Q43: 5796.9 | T43: ECOSISTEMAS SANITARIOS S A - Pago 1 | U43: DavD | V43: PGE C30
A44: 2904 | B44: =IF(G44="-",0,IF(G43=G44,1,0)) -> 0 | C44: =+IF(G44="-",0,IF(I44=I43+1,0,(IF(I44=1,0,1)))) -> 1 | D44: =+IF(AND(P44="",Q44=""),1,0) -> 0 | E44: =IF(U44="",1,0) -> 0 | F44: =IF(V44="",1,0) -> 0 | G44: =IF(H44=0,"-",_xlfn.CONCAT(K44,N44,O44,J44)) -> 24121909 | H44: 45645 | I44: 9 | J44: =+IF(I44<10,_xlfn.CONCAT("0",I44),I44) -> 09 | K44: =+YEAR(H44)-2000 -> 24 | L44: =+MONTH(H44) -> 12 | M44: =+DAY(H44) -> 19 | N44: =+IF(L44<10,_xlfn.CONCAT("0",L44),L44) -> 12 | O44: =+IF(M44<10,_xlfn.CONCAT("0",M44),M44) -> 19 | Q44: 5714.65 | T44: CUBIERTAS INTEGRALES AG LTDA - Cielo Vivo - Cancela C30 | U44: BacD | V44: PGE C30
...

Sheet 2024 b31
G1: id iguales? | H1: =SUM(B:B) -> 0
G2: id consecutivos? | H2: =SUM(C:C) -> 219
G3: sin precio | H3: =SUM(D:D) -> #REF!
G4: sin formade pago | H4: =SUM(E:E) -> 93
G5: sin centro de costo | H5: =SUM(F:F) -> 0
B7: id iguales? | C7: id consecutivos? | D7: sin precio | E7: sin formade pago | F7: sin centro de costo | G7: identificador | H7: Fecha | I7: diario | P7: colones | Q7: dolares | R7: Tipo Cambio | S7: Precio en $ | T7: Descripcion | U7: forma de pago | W7: Observaciones
J8: =+IF(I8<10,_xlfn.CONCAT("0",I8),I8) -> 0 | K8: =+YEAR(H8)-2000 -> -100 | L8: =+MONTH(H8) -> 1 | M8: =+DAY(H8) -> 0 | N8: =+IF(L8<10,_xlfn.CONCAT("0",L8),L8) -> 01 | O8: =+IF(M8<10,_xlfn.CONCAT("0",M8),M8) -> 00
J9: =+IF(I9<10,_xlfn.CONCAT("0",I9),I9) -> 0 | K9: =+YEAR(H9)-2000 -> -100 | L9: =+MONTH(H9) -> 1 | M9: =+DAY(H9) -> 0 | N9: =+IF(L9<10,_xlfn.CONCAT("0",L9),L9) -> 01 | O9: =+IF(M9<10,_xlfn.CONCAT("0",M9),M9) -> 00
J10: =+IF(I10<10,_xlfn.CONCAT("0",I10),I10) -> 0 | K10: =+YEAR(H10)-2000 -> -100 | L10: =+MONTH(H10) -> 1 | M10: =+DAY(H10) -> 0 | N10: =+IF(L10<10,_xlfn.CONCAT("0",L10),L10) -> 01 | O10: =+IF(M10<10,_xlfn.CONCAT("0",M10),M10) -> 00
J11: =+IF(I11<10,_xlfn.CONCAT("0",I11),I11) -> 0 | K11: =+YEAR(H11)-2000 -> -100 | L11: =+MONTH(H11) -> 1 | M11: =+DAY(H11) -> 0 | N11: =+IF(L11<10,_xlfn.CONCAT("0",L11),L11) -> 01 | O11: =+IF(M11<10,_xlfn.CONCAT("0",M11),M11) -> 00
A12: 6 | H12: 45377 | Q12: 3 | T12: comision | U12: DavD | V12: PGE B31
A13: 5 | H13: 45377 | Q13: 239.15 | T13: deposito de garantia coopeguanacaste | U13: DavD | V13: PGE B31
J14: =+IF(I14<10,_xlfn.CONCAT("0",I14),I14) -> 0 | K14: =+YEAR(H14)-2000 -> -100 | L14: =+MONTH(H14) -> 1 | M14: =+DAY(H14) -> 0 | N14: =+IF(L14<10,_xlfn.CONCAT("0",L14),L14) -> 01 | O14: =+IF(M14<10,_xlfn.CONCAT("0",M14),M14) -> 00
J15: =+IF(I15<10,_xlfn.CONCAT("0",I15),I15) -> 0 | K15: =+YEAR(H15)-2000 -> -100 | L15: =+MONTH(H15) -> 1 | M15: =+DAY(H15) -> 0 | N15: =+IF(L15<10,_xlfn.CONCAT("0",L15),L15) -> 01 | O15: =+IF(M15<10,_xlfn.CONCAT("0",M15),M15) -> 00
J16: =+IF(I16<10,_xlfn.CONCAT("0",I16),I16) -> 0 | K16: =+YEAR(H16)-2000 -> -100 | L16: =+MONTH(H16) -> 1 | M16: =+DAY(H16) -> 0 | N16: =+IF(L16<10,_xlfn.CONCAT("0",L16),L16) -> 01 | O16: =+IF(M16<10,_xlfn.CONCAT("0",M16),M16) -> 00
J17: =+IF(I17<10,_xlfn.CONCAT("0",I17),I17) -> 0 | K17: =+YEAR(H17)-2000 -> -100 | L17: =+MONTH(H17) -> 1 | M17: =+DAY(H17) -> 0 | N17: =+IF(L17<10,_xlfn.CONCAT("0",L17),L17) -> 01 | O17: =+IF(M17<10,_xlfn.CONCAT("0",M17),M17) -> 00
J18: =+IF(I18<10,_xlfn.CONCAT("0",I18),I18) -> 0 | K18: =+YEAR(H18)-2000 -> -100 | L18: =+MONTH(H18) -> 1 | M18: =+DAY(H18) -> 0 | N18: =+IF(L18<10,_xlfn.CONCAT("0",L18),L18) -> 01 | O18: =+IF(M18<10,_xlfn.CONCAT("0",M18),M18) -> 00
J19: =+IF(I19<10,_xlfn.CONCAT("0",I19),I19) -> 0 | K19: =+YEAR(H19)-2000 -> -100 | L19: =+MONTH(H19) -> 1 | M19: =+DAY(H19) -> 0 | N19: =+IF(L19<10,_xlfn.CONCAT("0",L19),L19) -> 01 | O19: =+IF(M19<10,_xlfn.CONCAT("0",M19),M19) -> 00
J20: =+IF(I20<10,_xlfn.CONCAT("0",I20),I20) -> 0 | K20: =+YEAR(H20)-2000 -> -100 | L20: =+MONTH(H20) -> 1 | M20: =+DAY(H20) -> 0 | N20: =+IF(L20<10,_xlfn.CONCAT("0",L20),L20) -> 01 | O20: =+IF(M20<10,_xlfn.CONCAT("0",M20),M20) -> 00
J21: =+IF(I21<10,_xlfn.CONCAT("0",I21),I21) -> 0 | K21: =+YEAR(H21)-2000 -> -100 | L21: =+MONTH(H21) -> 1 | M21: =+DAY(H21) -> 0 | N21: =+IF(L21<10,_xlfn.CONCAT("0",L21),L21) -> 01 | O21: =+IF(M21<10,_xlfn.CONCAT("0",M21),M21) -> 00
J22: =+IF(I22<10,_xlfn.CONCAT("0",I22),I22) -> 0 | K22: =+YEAR(H22)-2000 -> -100 | L22: =+MONTH(H22) -> 1 | M22: =+DAY(H22) -> 0 | N22: =+IF(L22<10,_xlfn.CONCAT("0",L22),L22) -> 01 | O22: =+IF(M22<10,_xlfn.CONCAT("0",M22),M22) -> 00
J23: =+IF(I23<10,_xlfn.CONCAT("0",I23),I23) -> 0 | K23: =+YEAR(H23)-2000 -> -100 | L23: =+MONTH(H23) -> 1 | M23: =+DAY(H23) -> 0 | N23: =+IF(L23<10,_xlfn.CONCAT("0",L23),L23) -> 01 | O23: =+IF(M23<10,_xlfn.CONCAT("0",M23),M23) -> 00
J24: =+IF(I24<10,_xlfn.CONCAT("0",I24),I24) -> 0 | K24: =+YEAR(H24)-2000 -> -100 | L24: =+MONTH(H24) -> 1 | M24: =+DAY(H24) -> 0 | N24: =+IF(L24<10,_xlfn.CONCAT("0",L24),L24) -> 01 | O24: =+IF(M24<10,_xlfn.CONCAT("0",M24),M24) -> 00
J25: =+IF(I25<10,_xlfn.CONCAT("0",I25),I25) -> 0 | K25: =+YEAR(H25)-2000 -> -100 | L25: =+MONTH(H25) -> 1 | M25: =+DAY(H25) -> 0 | N25: =+IF(L25<10,_xlfn.CONCAT("0",L25),L25) -> 01 | O25: =+IF(M25<10,_xlfn.CONCAT("0",M25),M25) -> 00
... J68: =+IF(I68<10,_xlfn.CONCAT("0",I68),I68) -> 0 | K68: =+YEAR(H68)-2000 -> -100 | L68: =+MONTH(H68) -> 1 | M68: =+DAY(H68) -> 0 | N68: =+IF(L68<10,_xlfn.CONCAT("0",L68),L68) -> 01 | O68: =+IF(M68<10,_xlfn.CONCAT("0",M68),M68) -> 00
A69: 62 | B69: =IF(G69="-",0,IF(G68=G69,1,0)) -> 0 | C69: =+IF(G69="-",0,IF(I69=I68+1,0,(IF(I69=1,0,1)))) -> 0 | D69: =+IF(AND(P69="",Q69=""),1,0) -> 0 | E69: =IF(U69="",1,0) -> 0 | F69: =IF(V69="",1,0) -> 0 | G69: =IF(H69=0,"-",_xlfn.CONCAT(K69,N69,O69,J69)) -> 24040101 | H69: 45383 | I69: 1 | J69: =+IF(I69<10,_xlfn.CONCAT("0",I69),I69) -> 01 | K69: =+YEAR(H69)-2000 -> 24 | L69: =+MONTH(H69) -> 4 | M69: =+DAY(H69) -> 1 | N69: =+IF(L69<10,_xlfn.CONCAT("0",L69),L69) -> 04 | O69: =+IF(M69<10,_xlfn.CONCAT("0",M69),M69) -> 01 | P69: 550000 | R69: 495 | S69: =+P69/R69 -> 1111.1111 | T69: Evelio - Herramienta y equipo de evelio CR80010200009565415850 | U69: DavD | V69: PGE B31
A70: 63 | B70: =IF(G70="-",0,IF(G69=G70,1,0)) -> 0 | C70: =+IF(G70="-",0,IF(I70=I69+1,0,(IF(I70=1,0,1)))) -> 0 | D70: =+IF(AND(P70="",Q70=""),1,0) -> 0 | E70: =IF(U70="",1,0) -> 0 | F70: =IF(V70="",1,0) -> 0 | G70: =IF(H70=0,"-",_xlfn.CONCAT(K70,N70,O70,J70)) -> 24040102 | H70: 45383 | I70: 2 | J70: =+IF(I70<10,_xlfn.CONCAT("0",I70),I70) -> 02 | K70: =+YEAR(H70)-2000 -> 24 | L70: =+MONTH(H70) -> 4 | M70: =+DAY(H70) -> 1 | N70: =+IF(L70<10,_xlfn.CONCAT("0",L70),L70) -> 04 | O70: =+IF(M70<10,_xlfn.CONCAT("0",M70),M70) -> 01 | Q70: 3 | T70: comision | U70: DavD | V70: PGE B31
J71: =+IF(I71<10,_xlfn.CONCAT("0",I71),I71) -> 0 | K71: =+YEAR(H71)-2000 -> -100 | L71: =+MONTH(H71) -> 1 | M71: =+DAY(H71) -> 0 | N71: =+IF(L71<10,_xlfn.CONCAT("0",L71),L71) -> 01 | O71: =+IF(M71<10,_xlfn.CONCAT("0",M71),M71) -> 00
J72: =+IF(I72<10,_xlfn.CONCAT("0",I72),I72) -> 0 | K72: =+YEAR(H72)-2000 -> -100 | L72: =+MONTH(H72) -> 1 | M72: =+DAY(H72) -> 0 | N72: =+IF(L72<10,_xlfn.CONCAT("0",L72),L72) -> 01 | O72: =+IF(M72<10,_xlfn.CONCAT("0",M72),M72) -> 00
J73: =+IF(I73<10,_xlfn.CONCAT("0",I73),I73) -> 0 | K73: =+YEAR(H73)-2000 -> -100 | L73: =+MONTH(H73) -> 1 | M73: =+DAY(H73) -> 0 | N73: =+IF(L73<10,_xlfn.CONCAT("0",L73),L73) -> 01 | O73: =+IF(M73<10,_xlfn.CONCAT("0",M73),M73) -> 00
J74: =+IF(I74<10,_xlfn.CONCAT("0",I74),I74) -> 0 | K74: =+YEAR(H74)-2000 -> -100 | L74: =+MONTH(H74) -> 1 | M74: =+DAY(H74) -> 0 | N74: =+IF(L74<10,_xlfn.CONCAT("0",L74),L74) -> 01 | O74: =+IF(M74<10,_xlfn.CONCAT("0",M74),M74) -> 00
J75: =+IF(I75<10,_xlfn.CONCAT("0",I75),I75) -> 0 | K75: =+YEAR(H75)-2000 -> -100 | L75: =+MONTH(H75) -> 1 | M75: =+DAY(H75) -> 0 | N75: =+IF(L75<10,_xlfn.CONCAT("0",L75),L75) -> 01 | O75: =+IF(M75<10,_xlfn.CONCAT("0",M75),M75) -> 00
J76: =+IF(I76<10,_xlfn.CONCAT("0",I76),I76) -> 0 | K76: =+YEAR(H76)-2000 -> -100 | L76: =+MONTH(H76) -> 1 | M76: =+DAY(H76) -> 0 | N76: =+IF(L76<10,_xlfn.CONCAT("0",L76),L76) -> 01 | O76: =+IF(M76<10,_xlfn.CONCAT("0",M76),M76) -> 00
J77: =+IF(I77<10,_xlfn.CONCAT("0",I77),I77) -> 0 | K77: =+YEAR(H77)-2000 -> -100 | L77: =+MONTH(H77) -> 1 | M77: =+DAY(H77) -> 0 | N77: =+IF(L77<10,_xlfn.CONCAT("0",L77),L77) -> 01 | O77: =+IF(M77<10,_xlfn.CONCAT("0",M77),M77) -> 00
J78: =+IF(I78<10,_xlfn.CONCAT("0",I78),I78) -> 0 | K78: =+YEAR(H78)-2000 -> -100 | L78: =+MONTH(H78) -> 1 | M78: =+DAY(H78) -> 0 | N78: =+IF(L78<10,_xlfn.CONCAT("0",L78),L78) -> 01 | O78: =+IF(M78<10,_xlfn.CONCAT("0",M78),M78) -> 00
J79: =+IF(I79<10,_xlfn.CONCAT("0",I79),I79) -> 0 | K79: =+YEAR(H79)-2000 -> -100 | L79: =+MONTH(H79) -> 1 | M79: =+DAY(H79) -> 0 | N79: =+IF(L79<10,_xlfn.CONCAT("0",L79),L79) -> 01 | O79: =+IF(M79<10,_xlfn.CONCAT("0",M79),M79) -> 00
J80: =+IF(I80<10,_xlfn.CONCAT("0",I80),I80) -> 0 | K80: =+YEAR(H80)-2000 -> -100 | L80: =+MONTH(H80) -> 1 | M80: =+DAY(H80) -> 0 | N80: =+IF(L80<10,_xlfn.CONCAT("0",L80),L80) -> 01 | O80: =+IF(M80<10,_xlfn.CONCAT("0",M80),M80) -> 00
J81: =+IF(I81<10,_xlfn.CONCAT("0",I81),I81) -> 0 | K81: =+YEAR(H81)-2000 -> -100 | L81: =+MONTH(H81) -> 1 | M81: =+DAY(H81) -> 0 | N81: =+IF(L81<10,_xlfn.CONCAT("0",L81),L81) -> 01 | O81: =+IF(M81<10,_xlfn.CONCAT("0",M81),M81) -> 00
J82: =+IF(I82<10,_xlfn.CONCAT("0",I82),I82) -> 0 | K82: =+YEAR(H82)-2000 -> -100 | L82: =+MONTH(H82) -> 1 | M82: =+DAY(H82) -> 0 | N82: =+IF(L82<10,_xlfn.CONCAT("0",L82),L82) -> 01 | O82: =+IF(M82<10,_xlfn.CONCAT("0",M82),M82) -> 00
... J158: =+IF(I158<10,_xlfn.CONCAT("0",I158),I158) -> 0 | K158: =+YEAR(H158)-2000 -> -100 | L158: =+MONTH(H158) -> 1 | M158: =+DAY(H158) -> 0 | N158: =+IF(L158<10,_xlfn.CONCAT("0",L158),L158) -> 01 | O158: =+IF(M158<10,_xlfn.CONCAT("0",M158),M158) -> 00
...

Sheet 2025 b31
G1: id iguales? | H1: =SUM(B:B) -> 2
G2: id consecutivos? | H2: =SUM(C:C) -> #VALUE!
G3: sin precio | H3: =SUM(D:D) -> 60
G4: sin formade pago | H4: =SUM(E:E) -> 152
G5: sin centro de costo | H5: =SUM(F:F) -> 60
A7: N | B7: id iguales? | C7: id consecutivos? | D7: sin precio | E7: sin formade pago | F7: sin centro de costo | G7: identificador | H7: Fecha | I7: Diario | J7: Column2 | K7: Column3 | L7: Column4 | M7: Column5 | N7: Column6 | O7: Column7 | P7: Colones | Q7: Dolares | R7: Tipo Cambio | S7: Precio en $ | T7: Descripcion | U7: forma de pago | V7: CC | W7: Medio | X7: FD | Y7: Observaciones
A8: 7 | B8: =IF(G8="-",0,IF(G7=G8,1,0)) -> 0 | C8: =+IF(G8="-",0,IF(I8=I7+1,0,(IF(I8=1,0,1)))) -> #VALUE! | D8: =+IF(AND(P8="",Q8=""),1,0) -> 0 | E8: =IF(U8="",1,0) -> 0 | F8: =IF(V8="",1,0) -> 0 | G8: =IF(H8=0,"-",_xlfn.CONCAT(K8,N8,O8,J8)) -> 25010201 | H8: 45659 | I8: 1 | J8: =+IF(I8<10,_xlfn.CONCAT("0",I8),I8) -> 01 | K8: =+YEAR(H8)-2000 -> 25 | L8: =+MONTH(H8) -> 1 | M8: =+DAY(H8) -> 2 | N8: =+IF(L8<10,_xlfn.CONCAT("0",L8),L8) -> 01 | O8: =+IF(M8<10,_xlfn.CONCAT("0",M8),M8) -> 02 | P8: 44592.69 | T8: Almacenes El Colono SA - Huacas - Trampa de Grasa | U8: Grillo | V8: PGE B31 | W8: Terceros | X8: ✓
A9: 8 | B9: =IF(G9="-",0,IF(G8=G9,1,0)) -> 0 | C9: =+IF(G9="-",0,IF(I9=I8+1,0,(IF(I9=1,0,1)))) -> 0 | D9: =+IF(AND(P9="",Q9=""),1,0) -> 0 | E9: =IF(U9="",1,0) -> 0 | F9: =IF(V9="",1,0) -> 0 | G9: =IF(H9=0,"-",_xlfn.CONCAT(K9,N9,O9,J9)) -> 25010202 | H9: 45659 | I9: 2 | J9: =+IF(I9<10,_xlfn.CONCAT("0",I9),I9) -> 02 | K9: =+YEAR(H9)-2000 -> 25 | L9: =+MONTH(H9) -> 1 | M9: =+DAY(H9) -> 2 | N9: =+IF(L9<10,_xlfn.CONCAT("0",L9),L9) -> 01 | O9: =+IF(M9<10,_xlfn.CONCAT("0",M9),M9) -> 02 | P9: 16549.98 | T9: Almacenes El Colono SA - Huacas - Cinta Led | U9: Grillo | V9: PGE B31 | W9: Terceros | X9: ✓
A10: 9 | B10: =IF(G10="-",0,IF(G9=G10,1,0)) -> 0 | C10: =+IF(G10="-",0,IF(I10=I9+1,0,(IF(I10=1,0,1)))) -> 0 | D10: =+IF(AND(P10="",Q10=""),1,0) -> 0 | E10: =IF(U10="",1,0) -> 0 | F10: =IF(V10="",1,0) -> 0 | G10: =IF(H10=0,"-",_xlfn.CONCAT(K10,N10,O10,J10)) -> 25010203 | H10: 45659 | I10: 3 | J10: =+IF(I10<10,_xlfn.CONCAT("0",I10),I10) -> 03 | K10: =+YEAR(H10)-2000 -> 25 | L10: =+MONTH(H10) -> 1 | M10: =+DAY(H10) -> 2 | N10: =+IF(L10<10,_xlfn.CONCAT("0",L10),L10) -> 01 | O10: =+IF(M10<10,_xlfn.CONCAT("0",M10),M10) -> 02 | P10: 5304.14 | T10: MAFERCO S.A. - Ref 267512 - Broca | U10: Grillo | V10: PGE C30 | W10: Terceros | X10: ✓
J11: =+IF(I11<10,_xlfn.CONCAT("0",I11),I11) -> 0 | K11: =+YEAR(H11)-2000 -> -100 | L11: =+MONTH(H11) -> 1 | M11: =+DAY(H11) -> 0 | N11: =+IF(L11<10,_xlfn.CONCAT("0",L11),L11) -> 01 | O11: =+IF(M11<10,_xlfn.CONCAT("0",M11),M11) -> 00
A12: 1 | D12: =+IF(AND(P12="",Q12=""),1,0) -> 0 | E12: =IF(U12="",1,0) -> 0 | F12: =IF(V12="",1,0) -> 0 | G12: =IF(H12=0,"-",_xlfn.CONCAT(K12,N12,O12,J12)) -> 25010301 | H12: 45660 | I12: 1 | J12: =+IF(I12<10,_xlfn.CONCAT("0",I12),I12) -> 01 | K12: =+YEAR(H12)-2000 -> 25 | L12: =+MONTH(H12) -> 1 | M12: =+DAY(H12) -> 3 | N12: =+IF(L12<10,_xlfn.CONCAT("0",L12),L12) -> 01 | O12: =+IF(M12<10,_xlfn.CONCAT("0",M12),M12) -> 03 | P12: 200000 | T12: Caja Chica B31 - Exner Grillo | U12: BacD | V12: PGE B31 | W12: Transferencia | X12: ✓ | Y12: 1046
J13: =+IF(I13<10,_xlfn.CONCAT("0",I13),I13) -> 0 | K13: =+YEAR(H13)-2000 -> -100 | L13: =+MONTH(H13) -> 1 | M13: =+DAY(H13) -> 0 | N13: =+IF(L13<10,_xlfn.CONCAT("0",L13),L13) -> 01 | O13: =+IF(M13<10,_xlfn.CONCAT("0",M13),M13) -> 00
J14: =+IF(I14<10,_xlfn.CONCAT("0",I14),I14) -> 0 | K14: =+YEAR(H14)-2000 -> -100 | L14: =+MONTH(H14) -> 1 | M14: =+DAY(H14) -> 0 | N14: =+IF(L14<10,_xlfn.CONCAT("0",L14),L14) -> 01 | O14: =+IF(M14<10,_xlfn.CONCAT("0",M14),M14) -> 00
A15: 4 | B15: =IF(G15="-",0,IF(G14=G15,1,0)) -> 0 | C15: =+IF(G15="-",0,IF(I15=I14+1,0,(IF(I15=1,0,1)))) -> 1 | D15: =+IF(AND(P15="",Q15=""),1,0) -> 0 | E15: =IF(U15="",1,0) -> 0 | F15: =IF(V15="",1,0) -> 0 | G15: =IF(H15=0,"-",_xlfn.CONCAT(K15,N15,O15,J15)) -> 25010304 | H15: 45660 | I15: 4 | J15: =+IF(I15<10,_xlfn.CONCAT("0",I15),I15) -> 04 | K15: =+YEAR(H15)-2000 -> 25 | L15: =+MONTH(H15) -> 1 | M15: =+DAY(H15) -> 3 | N15: =+IF(L15<10,_xlfn.CONCAT("0",L15),L15) -> 01 | O15: =+IF(M15<10,_xlfn.CONCAT("0",M15),M15) -> 03 | P15: 54008.32 | T15: Coopeguanacaste RL - Electricidad Ref 206349 | U15: BacC | V15: PGE B31 | W15: Transferencia | Y15: 1046
A16: 10 | B16: =IF(G16="-",0,IF(G15=G16,1,0)) -> 0 | C16: =+IF(G16="-",0,IF(I16=I15+1,0,(IF(I16=1,0,1)))) -> 0 | D16: =+IF(AND(P16="",Q16=""),1,0) -> 0 | E16: =IF(U16="",1,0) -> 0 | F16: =IF(V16="",1,0) -> 0 | G16: =IF(H16=0,"-",_xlfn.CONCAT(K16,N16,O16,J16)) -> 25010305 | H16: 45660 | I16: 5 | J16: =+IF(I16<10,_xlfn.CONCAT("0",I16),I16) -> 05 | K16: =+YEAR(H16)-2000 -> 25 | L16: =+MONTH(H16) -> 1 | M16: =+DAY(H16) -> 3 | N16: =+IF(L16<10,_xlfn.CONCAT("0",L16),L16) -> 01 | O16: =+IF(M16<10,_xlfn.CONCAT("0",M16),M16) -> 03 | P16: 39892.55 | T16: MAFERCO S.A. - Ref 103391 - Piedra Quinta Blanca 2m3 | U16: Grillo | V16: PGE C30 | W16: Terceros | X16: ✓
J17: =+IF(I17<10,_xlfn.CONCAT("0",I17),I17) -> 0 | K17: =+YEAR(H17)-2000 -> -100 | L17: =+MONTH(H17) -> 1 | M17: =+DAY(H17) -> 0 | N17: =+IF(L17<10,_xlfn.CONCAT("0",L17),L17) -> 01 | O17: =+IF(M17<10,_xlfn.CONCAT("0",M17),M17) -> 00
A18: 15 | B18: =IF(G18="-",0,IF(G17=G18,1,0)) -> 0 | C18: =+IF(G18="-",0,IF(I18=I17+1,0,(IF(I18=1,0,1)))) -> 1 | D18: =+IF(AND(P18="",Q18=""),1,0) -> 0 | E18: =IF(U18="",1,0) -> 0 | F18: =IF(V18="",1,0) -> 0 | G18: =IF(H18=0,"-",_xlfn.CONCAT(K18,N18,O18,J18)) -> 25010307 | H18: 45660 | I18: 7 | J18: =+IF(I18<10,_xlfn.CONCAT("0",I18),I18) -> 07 | K18: =+YEAR(H18)-2000 -> 25 | L18: =+MONTH(H18) -> 1 | M18: =+DAY(H18) -> 3 | N18: =+IF(L18<10,_xlfn.CONCAT("0",L18),L18) -> 01 | O18: =+IF(M18<10,_xlfn.CONCAT("0",M18),M18) -> 03 | P18: 30000 | T18: Wagner Zepeda Bustos [8770-8682] - Transporte Quintilla | U18: Grillo | V18: PGE C30 | W18: SINPE Movil | X18: × | Y18: 8433
A19: 262 | B19: =IF(G19="-",0,IF(G18=G19,1,0)) -> 0 | C19: =+IF(G19="-",0,IF(I19=I18+1,0,(IF(I19=1,0,1)))) -> 0 | D19: =+IF(AND(P18="",Q19=""),1,0) -> 0 | E19: =IF(U19="",1,0) -> 0 | F19: =IF(V19="",1,0) -> 0 | G19: =IF(H19=0,"-",_xlfn.CONCAT(K19,N19,O19,J19)) -> 25010308 | H19: 45660 | I19: 8 | J19: =+IF(I19<10,_xlfn.CONCAT("0",I19),I19) -> 08 | K19: =+YEAR(H19)-2000 -> 25 | L19: =+MONTH(H19) -> 1 | M19: =+DAY(H19) -> 3 | N19: =+IF(L19<10,_xlfn.CONCAT("0",L19),L19) -> 01 | O19: =+IF(M19<10,_xlfn.CONCAT("0",M19),M19) -> 03 | P19: 10000 | T19: Combustible - SERVIMOVIL HUACAS S.A (Viaticos Grillo) | U19: Grillo | V19: PGE B31 | W19: Terceros | X19: ✓
J20: =+IF(I20<10,_xlfn.CONCAT("0",I20),I20) -> 0 | K20: =+YEAR(H20)-2000 -> -100 | L20: =+MONTH(H20) -> 1 | M20: =+DAY(H20) -> 0 | N20: =+IF(L20<10,_xlfn.CONCAT("0",L20),L20) -> 01 | O20: =+IF(M20<10,_xlfn.CONCAT("0",M20),M20) -> 00
J21: =+IF(I21<10,_xlfn.CONCAT("0",I21),I21) -> 0 | K21: =+YEAR(H21)-2000 -> -100 | L21: =+MONTH(H21) -> 1 | M21: =+DAY(H21) -> 0 | N21: =+IF(L21<10,_xlfn.CONCAT("0",L21),L21) -> 01 | O21: =+IF(M21<10,_xlfn.CONCAT("0",M21),M21) -> 00
A22: 17 | B22: =IF(G22="-",0,IF(G21=G22,1,0)) -> 0 | C22: =+IF(G22="-",0,IF(I22=I21+1,0,(IF(I22=1,0,1)))) -> 1 | D22: =+IF(AND(P22="",Q22=""),1,0) -> 0 | E22: =IF(U22="",1,0) -> 0 | F22: =IF(V22="",1,0) -> 0 | G22: =IF(H22=0,"-",_xlfn.CONCAT(K22,N22,O22,J22)) -> 25010502 | H22: 45662 | I22: 2 | J22: =+IF(I22<10,_xlfn.CONCAT("0",I22),I22) -> 02 | K22: =+YEAR(H22)-2000 -> 25 | L22: =+MONTH(H22) -> 1 | M22: =+DAY(H22) -> 5 | N22: =+IF(L22<10,_xlfn.CONCAT("0",L22),L22) -> 01 | O22: =+IF(M22<10,_xlfn.CONCAT("0",M22),M22) -> 05 | P22: 21200 | T22: B31 Planilla 31 diciembre al 4 enero - Geyvin Centeno | U22: BacC | V22: PGE B31 | W22: Transferencia | X22: × | Y22: *0081
A23: 18 | B23: =IF(G23="-",0,IF(G22=G23,1,0)) -> 0 | C23: =+IF(G23="-",0,IF(I23=I22+1,0,(IF(I23=1,0,1)))) -> 0 | D23: =+IF(AND(P23="",Q23=""),1,0) -> 0 | E23: =IF(U23="",1,0) -> 0 | F23: =IF(V23="",1,0) -> 0 | G23: =IF(H23=0,"-",_xlfn.CONCAT(K23,N23,O23,J23)) -> 25010503 | H23: 45662 | I23: 3 | J23: =+IF(I23<10,_xlfn.CONCAT("0",I23),I23) -> 03 | K23: =+YEAR(H23)-2000 -> 25 | L23: =+MONTH(H23) -> 1 | M23: =+DAY(H23) -> 5 | N23: =+IF(L23<10,_xlfn.CONCAT("0",L23),L23) -> 01 | O23: =+IF(M23<10,_xlfn.CONCAT("0",M23),M23) -> 05 | P23: 17600 | T23: B31 Planilla 31 diciembre al 4 enero - Eliceo García Espinosa | U23: BacC | V23: PGE B31 | W23: Transferencia | X23: × | Y23: *0081
A24: 19 | B24: =IF(G24="-",0,IF(G23=G24,1,0)) -> 0 | C24: =+IF(G24="-",0,IF(I24=I23+1,0,(IF(I24=1,0,1)))) -> 0 | D24: =+IF(AND(P24="",Q24=""),1,0) -> 0 | E24: =IF(U24="",1,0) -> 0 | F24: =IF(V24="",1,0) -> 0 | G24: =IF(H24=0,"-",_xlfn.CONCAT(K24,N24,O24,J24)) -> 25010504 | H24: 45662 | I24: 4 | J24: =+IF(I24<10,_xlfn.CONCAT("0",I24),I24) -> 04 | K24: =+YEAR(H24)-2000 -> 25 | L24: =+MONTH(H24) -> 1 | M24: =+DAY(H24) -> 5 | N24: =+IF(L24<10,_xlfn.CONCAT("0",L24),L24) -> 01 | O24: =+IF(M24<10,_xlfn.CONCAT("0",M24),M24) -> 05 | P24: 138000 | T24: B31 Planilla 31 diciembre al 4 enero - Omar Elias Castillo Castillo. DEPOSITA A MARTA PEREZ | U24: BacC | V24: PGE B31 | W24: Transferencia | X24: × | Y24: *0081
A25: 20 | B25: =IF(G25="-",0,IF(G24=G25,1,0)) -> 0 | C25: =+IF(G25="-",0,IF(I25=I24+1,0,(IF(I25=1,0,1)))) -> 0 | D25: =+IF(AND(P25="",Q25=""),1,0) -> 0 | E25: =IF(U25="",1,0) -> 0 | F25: =IF(V25="",1,0) -> 0 | G25: =IF(H25=0,"-",_xlfn.CONCAT(K25,N25,O25,J25)) -> 25010505 | H25: 45662 | I25: 5 | J25: =+IF(I25<10,_xlfn.CONCAT("0",I25),I25) -> 05 | K25: =+YEAR(H25)-2000 -> 25 | L25: =+MONTH(H25) -> 1 | M25: =+DAY(H25) -> 5 | N25: =+IF(L25<10,_xlfn.CONCAT("0",L25),L25) -> 01 | O25: =+IF(M25<10,_xlfn.CONCAT("0",M25),M25) -> 05 | P25: 17600 | T25: B31 Planilla 31 diciembre al 4 enero - Eliecer Leonardo Lacayo | U25: BacC | V25: PGE B31 | W25: Transferencia | X25: × | Y25: *0081
A26: 21 | B26: =IF(G26="-",0,IF(G25=G26,1,0)) -> 0 | C26: =+IF(G26="-",0,IF(I26=I25+1,0,(IF(I26=1,0,1)))) -> 0 | D26: =+IF(AND(P26="",Q26=""),1,0) -> 0 | E26: =IF(U26="",1,0) -> 0 | F26: =IF(V26="",1,0) -> 0 | G26: =IF(H26=0,"-",_xlfn.CONCAT(K26,N26,O26,J26)) -> 25010506 | H26: 45662 | I26: 6 | J26: =+IF(I26<10,_xlfn.CONCAT("0",I26),I26) -> 06 | K26: =+YEAR(H26)-2000 -> 25 | L26: =+MONTH(H26) -> 1 | M26: =+DAY(H26) -> 5 | N26: =+IF(L26<10,_xlfn.CONCAT("0",L26),L26) -> 01 | O26: =+IF(M26<10,_xlfn.CONCAT("0",M26),M26) -> 05 | P26: 17600 | T26: B31 Planilla 31 diciembre al 4 enero - Freddy Antonio Hernandez | U26: BacC | V26: PGE B31 | W26: Transferencia | X26: × | Y26: *0081
A27: 22 | B27: =IF(G27="-",0,IF(G26=G27,1,0)) -> 0 | C27: =+IF(G27="-",0,IF(I27=I26+1,0,(IF(I27=1,0,1)))) -> 0 | D27: =+IF(AND(P27="",Q27=""),1,0) -> 0 | E27: =IF(U27="",1,0) -> 0 | F27: =IF(V27="",1,0) -> 0 | G27: =IF(H27=0,"-",_xlfn.CONCAT(K27,N27,O27,J27)) -> 25010507 | H27: 45662 | I27: 7 | J27: =+IF(I27<10,_xlfn.CONCAT("0",I27),I27) -> 07 | K27: =+YEAR(H27)-2000 -> 25 | L27: =+MONTH(H27) -> 1 | M27: =+DAY(H27) -> 5 | N27: =+IF(L27<10,_xlfn.CONCAT("0",L27),L27) -> 01 | O27: =+IF(M27<10,_xlfn.CONCAT("0",M27),M27) -> 05 | P27: 21200 | T27: B31 Planilla 31 diciembre al 4 enero - Michael Medina Corea | U27: BacC | V27: PGE B31 | W27: Transferencia | X27: × | Y27: *0081
A28: 23 | B28: =IF(G28="-",0,IF(G27=G28,1,0)) -> 0 | C28: =+IF(G28="-",0,IF(I28=I27+1,0,(IF(I28=1,0,1)))) -> 0 | D28: =+IF(AND(P28="",Q28=""),1,0) -> 0 | E28: =IF(U28="",1,0) -> 0 | F28: =IF(V28="",1,0) -> 0 | G28: =IF(H28=0,"-",_xlfn.CONCAT(K28,N28,O28,J28)) -> 25010508 | H28: 45662 | I28: 8 | J28: =+IF(I28<10,_xlfn.CONCAT("0",I28),I28) -> 08 | K28: =+YEAR(H28)-2000 -> 25 | L28: =+MONTH(H28) -> 1 | M28: =+DAY(H28) -> 5 | N28: =+IF(L28<10,_xlfn.CONCAT("0",L28),L28) -> 01 | O28: =+IF(M28<10,_xlfn.CONCAT("0",M28),M28) -> 05 | P28: 150000 | T28: B31 4 enero EXNER GRILLO - Comida | U28: BacC | V28: PGE B31 | W28: Transferencia | Y28: s7
A29: 24 | B29: =IF(G29="-",0,IF(G28=G29,1,0)) -> 0 | C29: =+IF(G29="-",0,IF(I29=I28+1,0,(IF(I29=1,0,1)))) -> 0 | D29: =+IF(AND(P29="",Q29=""),1,0) -> 0 | E29: =IF(U29="",1,0) -> 0 | F29: =IF(V29="",1,0) -> 0 | G29: =IF(H29=0,"-",_xlfn.CONCAT(K29,N29,O29,J29)) -> 25010509 | H29: 45662 | I29: 9 | J29: =+IF(I29<10,_xlfn.CONCAT("0",I29),I29) -> 09 | K29: =+YEAR(H29)-2000 -> 25 | L29: =+MONTH(H29) -> 1 | M29: =+DAY(H29) -> 5 | N29: =+IF(L29<10,_xlfn.CONCAT("0",L29),L29) -> 01 | O29: =+IF(M29<10,_xlfn.CONCAT("0",M29),M29) -> 05 | P29: 45800 | T29: CACERES_SALGADO - Fontaneria HARVYN Hernandez aguilar 4 ENERO - Cebolla - | U29: BacC | V29: PGE B31 | W29: Cheque | X29: ×
A30: 25 | B30: =IF(G30="-",0,IF(G29=G30,1,0)) -> 0 | C30: =+IF(G30="-",0,IF(I30=I29+1,0,(IF(I30=1,0,1)))) -> 0 | D30: =+IF(AND(P30="",Q30=""),1,0) -> 0 | E30: =IF(U30="",1,0) -> 0 | F30: =IF(V30="",1,0) -> 0 | G30: =IF(H30=0,"-",_xlfn.CONCAT(K30,N30,O30,J30)) -> 25010510 | H30: 45662 | I30: 10 | J30: =+IF(I30<10,_xlfn.CONCAT("0",I30),I30) -> 10 | K30: =+YEAR(H30)-2000 -> 25 | L30: =+MONTH(H30) -> 1 | M30: =+DAY(H30) -> 5 | N30: =+IF(L30<10,_xlfn.CONCAT("0",L30),L30) -> 01 | O30: =+IF(M30<10,_xlfn.CONCAT("0",M30),M30) -> 05 | P30: 412200 | T30: CACERES_SALGADO - Fontaneria_HARVYN_Hernandez_aguilar_4_ENERO__Cebolla | U30: BacC | V30: PGE B31 | W30: Transferencia | X30: ×
A31: 51 | B31: =IF(G31="-",0,IF(G30=G31,1,0)) -> 0 | C31: =+IF(G31="-",0,IF(I31=I30+1,0,(IF(I31=1,0,1)))) -> 0 | D31: =+IF(AND(P31="",Q31=""),1,0) -> 0 | E31: =IF(U31="",1,0) -> 0 | F31: =IF(V31="",1,0) -> 0 | G31: =IF(H31=0,"-",_xlfn.CONCAT(K31,N31,O31,J31)) -> 25010511 | H31: 45662 | I31: 11 | J31: =+IF(I31<10,_xlfn.CONCAT("0",I31),I31) -> 11 | K31: =+YEAR(H31)-2000 -> 25 | L31: =+MONTH(H31) -> 1 | M31: =+DAY(H31) -> 5 | N31: =+IF(L31<10,_xlfn.CONCAT("0",L31),L31) -> 01 | O31: =+IF(M31<10,_xlfn.CONCAT("0",M31),M31) -> 05 | P31: 132000 | T31: B31 Planilla 31 diciembre al 4 enero - Elvis Adrian Flores Vasquez - Depositar a | U31: BacC | V31: PGE B31 | W31: Transferencia
A32: 52 | B32: =IF(G32="-",0,IF(G31=G32,1,0)) -> 0 | C32: =+IF(G32="-",0,IF(I32=I31+1,0,(IF(I32=1,0,1)))) -> 0 | D32: =+IF(AND(P32="",Q32=""),1,0) -> 0 | E32: =IF(U32="",1,0) -> 0 | F32: =IF(V32="",1,0) -> 0 | G32: =IF(H32=0,"-",_xlfn.CONCAT(K32,N32,O32,J32)) -> 25010512 | H32: 45662 | I32: 12 | J32: =+IF(I32<10,_xlfn.CONCAT("0",I32),I32) -> 12 | K32: =+YEAR(H32)-2000 -> 25 | L32: =+MONTH(H32) -> 1 | M32: =+DAY(H32) -> 5 | N32: =+IF(L32<10,_xlfn.CONCAT("0",L32),L32) -> 01 | O32: =+IF(M32<10,_xlfn.CONCAT("0",M32),M32) -> 05 | P32: 14400 | T32: B31 Planilla 31 diciembre al 4 enero - Elvis Antonio Ramos Dormuz - Depositar a | U32: BacC | V32: PGE B31 | W32: Transferencia
A33: 53 | B33: =IF(G33="-",0,IF(G32=G33,1,0)) -> 0 | C33: =+IF(G33="-",0,IF(I33=I32+1,0,(IF(I33=1,0,1)))) -> 0 | D33: =+IF(AND(P33="",Q33=""),1,0) -> 0 | E33: =IF(U33="",1,0) -> 0 | F33: =IF(V33="",1,0) -> 0 | G33: =IF(H33=0,"-",_xlfn.CONCAT(K33,N33,O33,J33)) -> 25010513 | H33: 45662 | I33: 13 | J33: =+IF(I33<10,_xlfn.CONCAT("0",I33),I33) -> 13 | K33: =+YEAR(H33)-2000 -> 25 | L33: =+MONTH(H33) -> 1 | M33: =+DAY(H33) -> 5 | N33: =+IF(L33<10,_xlfn.CONCAT("0",L33),L33) -> 01 | O33: =+IF(M33<10,_xlfn.CONCAT("0",M33),M33) -> 05 | P33: 20000 | T33: B31 Planilla 31 diciembre al 4 enero - Crispin de Jesús Valencia - Depositar a | U33: BacC | V33: PGE B31 | W33: Transferencia
A34: 54 | B34: =IF(G34="-",0,IF(G33=G34,1,0)) -> 0 | C34: =+IF(G34="-",0,IF(I34=I33+1,0,(IF(I34=1,0,1)))) -> 0 | D34: =+IF(AND(P34="",Q34=""),1,0) -> 0 | E34: =IF(U34="",1,0) -> 0 | F34: =IF(V34="",1,0) -> 0 | G34: =IF(H34=0,"-",_xlfn.CONCAT(K34,N34,O34,J34)) -> 25010514 | H34: 45662 | I34: 14 | J34: =+IF(I34<10,_xlfn.CONCAT("0",I34),I34) -> 14 | K34: =+YEAR(H34)-2000 -> 25 | L34: =+MONTH(H34) -> 1 | M34: =+DAY(H34) -> 5 | N34: =+IF(L34<10,_xlfn.CONCAT("0",L34),L34) -> 01 | O34: =+IF(M34<10,_xlfn.CONCAT("0",M34),M34) -> 05 | P34: 17600 | T34: B31 Planilla 31 diciembre al 4 enero - Francisco Javier Rocha Orozco - Depositar a GRILLO | U34: BacC | V34: PGE B31 | W34: Transferencia
A35: 55 | B35: =IF(G35="-",0,IF(G34=G35,1,0)) -> 0 | C35: =+IF(G35="-",0,IF(I35=I34+1,0,(IF(I35=1,0,1)))) -> 0 | D35: =+IF(AND(P35="",Q35=""),1,0) -> 0 | E35: =IF(U35="",1,0) -> 0 | F35: =IF(V35="",1,0) -> 0 | G35: =IF(H35=0,"-",_xlfn.CONCAT(K35,N35,O35,J35)) -> 25010515 | H35: 45662 | I35: 15 | J35: =+IF(I35<10,_xlfn.CONCAT("0",I35),I35) -> 15 | K35: =+YEAR(H35)-2000 -> 25 | L35: =+MONTH(H35) -> 1 | M35: =+DAY(H35) -> 5 | N35: =+IF(L35<10,_xlfn.CONCAT("0",L35),L35) -> 01 | O35: =+IF(M35<10,_xlfn.CONCAT("0",M35),M35) -> 05 | P35: 108000 | T35: B31 Planilla 31 diciembre al 4 enero - Misael Ramos Dormuz - Depositar a | U35: BacC | V35: PGE B31 | W35: Transferencia
A36: 56 | B36: =IF(G36="-",0,IF(G35=G36,1,0)) -> 0 | C36: =+IF(G36="-",0,IF(I36=I35+1,0,(IF(I36=1,0,1)))) -> 0 | D36: =+IF(AND(P36="",Q36=""),1,0) -> 0 | E36: =IF(U36="",1,0) -> 0 | F36: =IF(V36="",1,0) -> 0 | G36: =IF(H36=0,"-",_xlfn.CONCAT(K36,N36,O36,J36)) -> 25010516 | H36: 45662 | I36: 16 | J36: =+IF(I36<10,_xlfn.CONCAT("0",I36),I36) -> 16 | K36: =+YEAR(H36)-2000 -> 25 | L36: =+MONTH(H36) -> 1 | M36: =+DAY(H36) -> 5 | N36: =+IF(L36<10,_xlfn.CONCAT("0",L36),L36) -> 01 | O36: =+IF(M36<10,_xlfn.CONCAT("0",M36),M36) -> 05 | P36: 14400 | T36: B31 Planilla 31 diciembre al 4 enero - Oscar Manuel Rocha | U36: BacC | V36: PGE B31 | W36: Transferencia
A37: 57 | B37: =IF(G37="-",0,IF(G36=G37,1,0)) -> 0 | C37: =+IF(G37="-",0,IF(I37=I36+1,0,(IF(I37=1,0,1)))) -> 0 | D37: =+IF(AND(P37="",Q37=""),1,0) -> 0 | E37: =IF(U37="",1,0) -> 0 | F37: =IF(V37="",1,0) -> 0 | G37: =IF(H37=0,"-",_xlfn.CONCAT(K37,N37,O37,J37)) -> 25010517 | H37: 45662 | I37: 17 | J37: =+IF(I37<10,_xlfn.CONCAT("0",I37),I37) -> 17 | K37: =+YEAR(H37)-2000 -> 25 | L37: =+MONTH(H37) -> 1 | M37: =+DAY(H37) -> 5 | N37: =+IF(L37<10,_xlfn.CONCAT("0",L37),L37) -> 01 | O37: =+IF(M37<10,_xlfn.CONCAT("0",M37),M37) -> 05 | P37: 14400 | T37: B31 Planilla 31 diciembre al 4 enero - Denis Damian Rocha Orozco | U37: BacC | V37: PGE B31 | W37: Transferencia
A38: 58 | B38: =IF(G38="-",0,IF(G37=G38,1,0)) -> 0 | C38: =+IF(G38="-",0,IF(I38=I37+1,0,(IF(I38=1,0,1)))) -> 0 | D38: =+IF(AND(P38="",Q38=""),1,0) -> 0 | E38: =IF(U38="",1,0) -> 0 | F38: =IF(V38="",1,0) -> 0 | G38: =IF(H38=0,"-",_xlfn.CONCAT(K38,N38,O38,J38)) -> 25010518 | H38: 45662 | I38: 18 | J38: =+IF(I38<10,_xlfn.CONCAT("0",I38),I38) -> 18 | K38: =+YEAR(H38)-2000 -> 25 | L38: =+MONTH(H38) -> 1 | M38: =+DAY(H38) -> 5 | N38: =+IF(L38<10,_xlfn.CONCAT("0",L38),L38) -> 01 | O38: =+IF(M38<10,_xlfn.CONCAT("0",M38),M38) -> 05 | P38: 252000 | T38: B31 Planilla 31 diciembre al 4 enero - EXNER GRILLO | U38: BacC | V38: PGE B31 | W38: Transferencia
A39: 59 | B39: =IF(G39="-",0,IF(G38=G39,1,0)) -> 0 | C39: =+IF(G39="-",0,IF(I39=I38+1,0,(IF(I39=1,0,1)))) -> 0 | D39: =+IF(AND(P39="",Q39=""),1,0) -> 0 | E39: =IF(U39="",1,0) -> 0 | F39: =IF(V39="",1,0) -> 0 | G39: =IF(H39=0,"-",_xlfn.CONCAT(K39,N39,O39,J39)) -> 25010519 | H39: 45662 | I39: 19 | J39: =+IF(I39<10,_xlfn.CONCAT("0",I39),I39) -> 19 | K39: =+YEAR(H39)-2000 -> 25 | L39: =+MONTH(H39) -> 1 | M39: =+DAY(H39) -> 5 | N39: =+IF(L39<10,_xlfn.CONCAT("0",L39),L39) -> 01 | O39: =+IF(M39<10,_xlfn.CONCAT("0",M39),M39) -> 05 | P39: 42000 | T39: B31 Planilla 31 diciembre al 4 enero - EXNER GRILLO feriado | U39: BacC | V39: PGE B31 | W39: Transferencia
A40: 60 | B40: =IF(G40="-",0,IF(G39=G40,1,0)) -> 0 | C40: =+IF(G40="-",0,IF(I40=I39+1,0,(IF(I40=1,0,1)))) -> 0 | D40: =+IF(AND(P40="",Q40=""),1,0) -> 0 | E40: =IF(U40="",1,0) -> 0 | F40: =IF(V40="",1,0) -> 0 | G40: =IF(H40=0,"-",_xlfn.CONCAT(K40,N40,O40,J40)) -> 25010520 | H40: 45662 | I40: 20 | J40: =+IF(I40<10,_xlfn.CONCAT("0",I40),I40) -> 20 | K40: =+YEAR(H40)-2000 -> 25 | L40: =+MONTH(H40) -> 1 | M40: =+DAY(H40) -> 5 | N40: =+IF(L40<10,_xlfn.CONCAT("0",L40),L40) -> 01 | O40: =+IF(M40<10,_xlfn.CONCAT("0",M40),M40) -> 05 | P40: 90000 | T40: B31 Planilla 31 diciembre al 4 enero - EXNER GRILLO viaticos | U40: BacC | V40: PGE B31 | W40: Transferencia
J41: =+IF(I41<10,_xlfn.CONCAT("0",I41),I41) -> 0 | K41: =+YEAR(H41)-2000 -> -100 | L41: =+MONTH(H41) -> 1 | M41: =+DAY(H41) -> 0 | N41: =+IF(L41<10,_xlfn.CONCAT("0",L41),L41) -> 01 | O41: =+IF(M41<10,_xlfn.CONCAT("0",M41),M41) -> 00
...
